Workbook

Sheet 總覽
A1: aibuddy 生產就緒追蹤
A2: 最後更新：2026-10-15 10:42 · 本頁由 tracker.py 自動生成，請勿手動編輯
A3: 總進度：25/93 已完成（27%） · 目前階段：1 止血定案（10/5–10/16）
A5: 優先級 | B5: 說明 | C5: 總數 | D5: 未開始 | E5: 進行中 | F5: 已完成 | G5: 阻塞 | H5: 不適用 | I5: 完成率
A6: P0 | B6: 安全：真實用戶使用前必須完成 | C6: =COUNTIF('任務清單'!$B:$B,$A6) -> 17 | D6: =COUNTIFS('任務清單'!$B:$B,$A6,'任務清單'!$F:$F,D$5) -> 1 | E6: =COUNTIFS('任務清單'!$B:$B,$A6,'任務清單'!$F:$F,E$5) -> 2 | F6: =COUNTIFS('任務清單'!$B:$B,$A6,'任務清單'!$F:$F,F$5) -> 13 | G6: =COUNTIFS('任務清單'!$B:$B,$A6,'任務清單'!$F:$F,G$5) -> 0 | H6: =COUNTIFS('任務清單'!$B:$B,$A6,'任務清單'!$F:$F,H$5) -> 1 | I6: =IFERROR(F6/(C6-H6),0) -> 0.8125
A7: P1 | B7: 兒童安全與合規：上市前必須完成 | C7: =COUNTIF('任務清單'!$B:$B,$A7) -> 14 | D7: =COUNTIFS('任務清單'!$B:$B,$A7,'任務清單'!$F:$F,D$5) -> 8 | E7: =COUNTIFS('任務清單'!$B:$B,$A7,'任務清單'!$F:$F,E$5) -> 3 | F7: =COUNTIFS('任務清單'!$B:$B,$A7,'任務清單'!$F:$F,F$5) -> 0 | G7: =COUNTIFS('任務清單'!$B:$B,$A7,'任務清單'!$F:$F,G$5) -> 2 | H7: =COUNTIFS('任務清單'!$B:$B,$A7,'任務清單'!$F:$F,H$5) -> 1 | I7: =IFERROR(F7/(C7-H7),0) -> 0
A8: P2 | B8: 工程與運維：規模化前完成 | C8: =COUNTIF('任務清單'!$B:$B,$A8) -> 25 | D8: =COUNTIFS('任務清單'!$B:$B,$A8,'任務清單'!$F:$F,D$5) -> 9 | E8: =COUNTIFS('任務清單'!$B:$B,$A8,'任務清單'!$F:$F,E$5) -> 6 | F8: =COUNTIFS('任務清單'!$B:$B,$A8,'任務清單'!$F:$F,F$5) -> 10 | G8: =COUNTIFS('任務清單'!$B:$B,$A8,'任務清單'!$F:$F,G$5) -> 0 | H8: =COUNTIFS('任務清單'!$B:$B,$A8,'任務清單'!$F:$F,H$5) -> 0 | I8: =IFERROR(F8/(C8-H8),0) -> 0.4
A9: R | B9: 產品與上市：1/15 出廠 3,000 隻（馬會 2,500、政協青年聯會 500）＋AI Buddy 數量未定 | C9: =COUNTIF('任務清單'!$B:$B,$A9) -> 41 | D9: =COUNTIFS('任務清單'!$B:$B,$A9,'任務清單'!$F:$F,D$5) -> 29 | E9: =COUNTIFS('任務清單'!$B:$B,$A9,'任務清單'!$F:$F,E$5) -> 5 | F9: =COUNTIFS('任務清單'!$B:$B,$A9,'任務清單'!$F:$F,F$5) -> 2 | G9: =COUNTIFS('任務清單'!$B:$B,$A9,'任務清單'!$F:$F,G$5) -> 3 | H9: =COUNTIFS('任務清單'!$B:$B,$A9,'任務清單'!$F:$F,H$5) -> 2 | I9: =IFERROR(F9/(C9-H9),0) -> 0.051282051
A10: 合計 | C10: =SUM(C6:C9) -> 97 | D10: =SUM(D6:D9) -> 47 | E10: =SUM(E6:E9) -> 16 | F10: =SUM(F6:F9) -> 25 | G10: =SUM(G6:G9) -> 5 | H10: =SUM(H6:H9) -> 4 | I10: =IFERROR(F10/(C10-H10),0) -> 0.2688172
A12: 階段 | B12: 說明 | C12: 總數 | D12: 未開始 | E12: 進行中 | F12: 已完成 | G12: 阻塞 | H12: 不適用 | I12: 完成率
A13: 1 止血定案 | B13: 10/5–10/16：安全修復、選板（10/16 定案）、角色收窄 | C13: =COUNTIF('任務清單'!$C:$C,$A13) -> 23 | D13: =COUNTIFS('任務清單'!$C:$C,$A13,'任務清單'!$F:$F,D$12) -> 1 | E13: =COUNTIFS('任務清單'!$C:$C,$A13,'任務清單'!$F:$F,E$12) -> 5 | F13: =COUNTIFS('任務清單'!$C:$C,$A13,'任務清單'!$F:$F,F$12) -> 15 | G13: =COUNTIFS('任務清單'!$C:$C,$A13,'任務清單'!$F:$F,G$12) -> 1 | H13: =COUNTIFS('任務清單'!$C:$C,$A13,'任務清單'!$F:$F,H$12) -> 1 | I13: =IFERROR(F13/(C13-H13),0) -> 0.68181818
A14: 2 內測準備 | B14: 10/19–10/30：粵語評測、內容審核、OTA、外殼、上手流程；10/30 CP1 內測就緒檢查 | C14: =COUNTIF('任務清單'!$C:$C,$A14) -> 37 | D14: =COUNTIFS('任務清單'!$C:$C,$A14,'任務清單'!$F:$F,D$12) -> 15 | E14: =COUNTIFS('任務清單'!$C:$C,$A14,'任務清單'!$F:$F,E$12) -> 8 | F14: =COUNTIFS('任務清單'!$C:$C,$A14,'任務清單'!$F:$F,F$12) -> 10 | G14: =COUNTIFS('任務清單'!$C:$C,$A14,'任務清單'!$F:$F,G$12) -> 2 | H14: =COUNTIFS('任務清單'!$C:$C,$A14,'任務清單'!$F:$F,H$12) -> 2 | I14: =IFERROR(F14/(C14-H14),0) -> 0.28571429
A15: 3 封閉內測 | B15: 11/2–11/27：內部測試（10/12 起取代 20 個家庭內測），並行送測認證與合規；11/27 CP2 定品牌 C 數量（R-08） | C15: =COUNTIF('任務清單'!$C:$C,$A15) -> 29 | D15: =COUNTIFS('任務清單'!$C:$C,$A15,'任務清單'!$F:$F,D$12) -> 23 | E15: =COUNTIFS('任務清單'!$C:$C,$A15,'任務清單'!$F:$F,E$12) -> 3 | F15: =COUNTIFS('任務清單'!$C:$C,$A15,'任務清單'!$F:$F,F$12) -> 0 | G15: =COUNTIFS('任務清單'!$C:$C,$A15,'任務清單'!$F:$F,G$12) -> 2 | H15: =COUNTIFS('任務清單'!$C:$C,$A15,'任務清單'!$F:$F,H$12) -> 1 | I15: =IFERROR(F15/(C15-H15),0) -> 0
A16: 4 量產出貨 | B16: 11/30–1/15：量產板到廠、試產 12/7、大貨 12/14–12/31、出廠流程、壓測、售後；1/15 出廠、1/29 送達。每週計劃見 docs/roadmap.md | C16: =COUNTIF('任務清單'!$C:$C,$A16) -> 8 | D16: =COUNTIFS('任務清單'!$C:$C,$A16,'任務清單'!$F:$F,D$12) -> 8 | E16: =COUNTIFS('任務清單'!$C:$C,$A16,'任務清單'!$F:$F,E$12) -> 0 | F16: =COUNTIFS('任務清單'!$C:$C,$A16,'任務清單'!$F:$F,F$12) -> 0 | G16: =COUNTIFS('任務清單'!$C:$C,$A16,'任務清單'!$F:$F,G$12) -> 0 | H16: =COUNTIFS('任務清單'!$C:$C,$A16,'任務清單'!$F:$F,H$12) -> 0 | I16: =IFERROR(F16/(C16-H16),0) -> 0
A17: 合計 | C17: =SUM(C13:C16) -> 97 | D17: =SUM(D13:D16) -> 47 | E17: =SUM(E13:E16) -> 16 | F17: =SUM(F13:F16) -> 25 | G17: =SUM(G13:G16) -> 5 | H17: =SUM(H13:H16) -> 4 | I17: =IFERROR(F17/(C17-H17),0) -> 0.2688172
A19: ⏭ 接下來做什麼
A20: 編號 | B20: 任務 | C20: 階段 | D20: 狀態 | E20: 驗收標準 / 上次測試
A21: P0-07 | B21: 輪換 JWT secret，作廢已發出的 token | C21: 1 止血定案 | D21: 進行中 | E21: ① 生產自架 Supabase 換上新的 JWT secret（app.settings.jwt_secret 一併更新），重發 anon／service_role key，更新到 Supabase 各容器、網頁（anon key 要重新建置 image）和語音伺服器。② 用舊 secret 簽的東西全部失效：舊 anon key、舊 service_role key、舊 secret 簽的無過期用戶 JWT（P0-06 前 MAC 換到的那種）。③ DEVICE_JWT_SECRET 同時輪換；設備不用重新配對（P0-06 之後設備靠 NVS 裡的設備密鑰自動換新 token）。④ 沒有任何運行中的容器還持有舊值；用到 service key 的其他地方（例如 Mac 上的 release_firmware.py）已改用新 key。⑤ 有回滾方法。
A22: P0-11 | B22: 設備認領要求持有證明 | C22: 1 止血定案 | D22: 進行中 | E22: 上次測試：部分通過 — 本機（分支 p0-11-bind-ticket da3709b，localhost:3015 + 本機 Supabase，測試腳本 22/22）：① 只帶 MAC → 401、密鑰 + user_code 當票 → 403 且設備仍無主 ② 票用過（另一台）／過期／本庫沒發過的票（他品牌）→ 403 ③ B 的票交給 A 的設備 → 409 device_owned，A 綁定不變、B 的票未作廢 ④ 有效票但無設備密鑰 → 401、票未作廢 ⑤ 密鑰 + 有效票 → 200 token，user_id 和 claimed_at 寫入；同一台重送同一張票 → 200 ⑥ DEVICE_CLAIM_LIST=False 時設定頁沒有未認領清單和配對碼欄，有未認領設備在線也看不到，12 秒內無輪詢；=True 時開發清單照舊可認領 ⑦ 同帳號並行 10 次取票 → 5×200、5×429，B 不受影響，滿一分鐘後恢復；表只存 SHA-256；authenticated 讀表／呼叫 RPC → 42501。未部署線上。 綁定票（用戶 2026-10-12 決定，經藍牙交付，見 R-21）：① 已登入的 App 向伺服器取綁定票：一次性、5 分鐘有效，綁定該帳號和品牌。② 設備連上 Wi-Fi 後，用設備密鑰加綁定票呼叫伺服器；伺服器在同一個交易裡檢查票有效、設備 user_id 為空、品牌相符，然後寫入 user_id 和 claimed_at，並把票作廢。③ 不再列出全球未認領設備，也不再用手動輸入的配對碼認領（舊流程只在開發模式保留）。④ 已有主人的設備不能被認領：原主在 App 內解綁，聯絡不到原主就由管理員在後台解綁（R-11）。⑤ 第一版一台設備只屬一個帳號。⑥ 取票有頻率上限（每帳號每分鐘 5 次）。
A23: P2-10 | B23: DeepSeek v4 flash 經 OpenRouter 時固定可用的供應商 | C23: 1 止血定案 | D23: 進行中 | E23: 上次測試：部分通過 — ① 16 家供應商各 20 次真實 session prompt（含開場白，串流，order=[x]+allow_fallbacks=false）：建議清單 azure/alibaba/novita/siliconflow/gmicloud 各 20/20，0 空內容 0 特殊 token，首字 p50 1.25/2.33/2.59/2.56/3.25s；只設 order 時 order=[deepinfra] 實際由 Relace 回應（回過 content=None）→ 已改為 allow_fallbacks=false。伺服器端 LLMOutputGuard：pytest 8 項（尾部/跨 chunk 拆開的 token、空回應記警告）全套 203 passed；真實 LLM 串流經 guard 6 角色 12/12 正常、無誤觸發。② 實機 5 次開場白未做 線上用 DeepSeek 時，provider_order 只列實測正常的供應商（例如 StreamLake、SiliconFlow、GMICloud、Novita），並開 reasoning；或線上改用 gemma-4-26b。伺服器遇到空回應或特殊 token 時不把它送去 TTS。
A24: R-01 | B24: 選定量產板子 | C24: 1 止血定案 | D24: 進行中 | E24: 已定案 Spotpear AI Toy（用戶 10/07 決定）；評分表 ①–⑦ 在 Spotpear 上實測並記錄結果，沒有否決性問題（如 2 小時內 OOM 重啟、C3 無法啟用 Secure Boot v2＋Flash 加密、無認證模組）。
A25: R-02 | B25: 角色收窄到 5–8 個粵語陪伴角色 | C25: 1 止血定案 | D25: 進行中 | E25: 上次測試：通過 — 用戶已確認角色陣容。本地 DB：① 未隱藏內建角色只剩 hk_ 6 個 ② localhost:3100 Children 頁只見 6 個、Story 頁只見叮叮兔/咪咪貓 ③ 每角色 10 句粵語，prompt 用伺服器同一套組裝、開場白按 pipecat 以 user 角色送出：gemma-4-26b 65/66 合格（1 句 4 句/2 問）；DeepSeek v4 flash 預設 reasoning 61/66（超標都只多 1–2 句）；全部無簡體、恐怖、拼字 只保留 5–8 個自己設計的粵語陪伴角色，其餘設為 is_hidden；每個角色按 3–6 歲設計：句子短、用詞簡單、一次只問一個問題，不講恐怖、暴力或需要識字的內容。
A26: P1-02 | B26: 日誌移除兒童個人資料 | C26: 2 內測準備 | D26: 進行中 | E26: 上次測試：部分通過 — 本機（分支 p1-02-log-pii）：模擬板子跑 3 輪，孩子名 PROBE小明、性格『鍾意恐龍』、記憶『佢有隻狗叫PROBE豆豆』；把對話、回覆、事實切成 47 段搜日誌 → 預設 INFO 0 段；同一流程 LOG_LEVEL=DEBUG → 27 段（證明搜尋有效）。INFO 日誌也無 token。pytest 245 passed（新增 test_log_privacy 6 項：事實/摘要、PostgREST details、OpenRouter flagged_input、非 JSON 回覆、預設 INFO 與 traceback 無變量值）。未做：部署線上並在生產日誌重跑。 生產日誌只記 ID、長度、類別，不記內容；內容只在 DEBUG 等級輸出，生產不開 DEBUG。
A27: P1-10 | B27: 管理操作審計記錄 | C27: 2 內測準備 | D27: 進行中 | E27: 上次測試：部分通過 — 本機（分支 p1-10-p2-09-audit-usage，migration 已套用到本機 Supabase）：探測腳本 22/22，用 GoTrue 真實登入、只把 42501 當拒絕。① 超管改角色 short_description → 1 筆 update、before/after 只有該欄、actor=該管理員；改 voice_stack → 1 筆含新舊值；不改內容再存 → 0 筆 ② 超管 JWT UPDATE/DELETE → 42501；service role DELETE → 42501；postgres DELETE/TRUNCATE 被觸發器拒絕；內容管理員、家長讀 → []；anon → 42501。網頁實測：IP 加一個活動提示 → 只記 1 筆 ip_modes insert，原樣再存 → 0 筆，清除 → 1 筆 delete；Accounts 建帳號 → account.create（不含密碼）；改匯率 → 1 筆。未做：部署線上。 每個管理操作寫一筆記錄：誰、什麼時間、什麼操作、對象、改之前與改之後的值；記錄只能新增，任何人（包括超級管理員）都不能修改或刪除；超級管理員能在管理端查看。
A28: P1-12 | B28: 設備解綁時的記憶處理：確認、預設保留、可選清除 | C28: 2 內測準備 | D28: 進行中 | E28: 上次測試：部分通過 — 本機（開發板 DEV636 身份的模擬裝置 + 網頁）：TC1/2/5/6/7/8/10/11/13 通過；TC3 重綁後 log『Loaded 2 fact(s)』；TC4 第二台 starts cold、設定頁可切換；TC9 DB 層 B 解綁回 NULL、清除報錯，anon/authenticated 無 EXECUTE；TC10 舊代數寫入三表皆 HTTP 400、清除後 40 秒仍 0 行；TC12 伺服器端 4401 通過；pytest 214 passed。TC14（2026-10-12，rebase 到 main 後的 p1-12-rebased 8d4b9e2，本機 7861）：/ws/nextjs 以網頁 token 對話兩輪，波波熊有回應 → turn_metrics 0→3，memory_facts／memory_segments／conversations 皆 0→0；log 只有 NextJS websocket connected。真機 62:70（2026-10-12，localall 測試版 → 本機 7861/3014，p1-12-rebased）：按住 BOOT 對話 6 輪，conversations 記下『我隻狗叫豆豆…』；TC12：介面解綁（不勾清除）→ 16:06:51 即斷線，之後每次重連都在 auth 前被拒（device token refused），16:07:02 重新取 token 得 202 並顯示配對碼 UKDM7N；facts 1→1、conversations 14→14、segments 1→2（結束時的摘要）、revision 0。TC3：同帳號重綁 → log『Loaded 1 fact(s)』（有一隻3歲嘅狗叫豆豆）＋2 段摘要；真機問『我隻狗叫咩名』的回答未記錄（用戶決定直接部署）。發現：韌體拿到 202 後 websocket 仍每秒重連一次直到被認領，沒有真正停在配對狀態（不屬 P1-12 伺服器端，另開任務）。 ① 按「解綁」先彈出確認對話框，取消則什麼都不改。② 對話框預設保留記憶；「同時清除記憶」要主動勾選，並寫明無法復原。③ 記憶跟設備：鍵是 (user_id, device_id, ip_key)。同一帳號的每台設備各自一份記憶；保留時，同帳號重綁同一台會接著用；換新設備從空白開始（搬記憶交給 R-11）。④ 清除在伺服器端一個交易完成：先刪該設備的 memory_facts、memory_segments、conversations（連帳號的舊 memories），再解綁；任何一步失敗就不解綁，並顯示錯誤。⑤ 其他帳號認領同一台設備，看不到舊記憶（靠 user_id 隔離，不靠刪除成功）。⑥ 設定頁按設備顯示記憶；「清除全部」只清所選設備，連 conversations 一起刪。⑦ 對話中清除，之後的寫入和 consolidation 不會把記憶寫回（devices.memories_revision + trigger）。⑧ 未認領的設備不能對話：/ws/esp32 查到設備沒有 user_id 就在 auth 前以 4401 關閉，即使 24 小時 token 未過期；韌體重新取 token 拿到 202，回到配對狀態。⑨ 解綁時立即中斷該設備正在進行的語音 session。⑩ 網頁語音（playground）沒有設備，不讀也不寫記憶。
A29: P2-09 | B29: 每台設備成本監控 | C29: 2 內測準備 | D29: 進行中 | E29: 上次測試：部分通過 — 本機：pytest 239 passed（新增 8 項：STT/TTS 用量入行、遲到的用量帶到下一行、session 結束寫 usage 行、設備 ID、同一輪多次 LLM 相加、記憶整理的 token 即使回覆解析失敗也記錄並記到該設備）。模擬板子跑 2 輪（本機語音伺服器 7865）：送 2.24s 音訊 → stt_audio_ms=2242（兩輪皆是）；每輪有 tts_chars、token、device_id；session 結束的記憶整理寫成 memory 行（deepseek-v4-flash 946/10 token）。Usage 頁按設備與日期顯示 HK$，改費率即重算並進審計。未做：抽 10 個 session 與 Azure/MiniMax/OpenRouter 帳單對帳（需用戶提供帳單）、部署線上。 每個 session 記錄 STT 秒數、LLM token、TTS 字數並換算成本；admin 頁顯示每台設備的月成本。
A30: P2-13 | B30: Admin 後台改成分組側欄（新頁面先用示例數據預覽） | C30: 2 內測準備 | D30: 進行中 | E30: 上次測試：部分通過 — ① tsc --noEmit 通過 ② 略過登入的測試頁（另一份副本、獨立 .next）：超級管理員 15 頁、內容管理員只見 Characters／IPs；1360px 與 375px 均無橫向捲動（scrollWidth=clientWidth=375）；#audit 直接打開正確；③④ 未做：需真實帳號登入 /admin 6 個現有分頁（Model、Latency、Characters、IPs、Accounts、Admins）在新側欄照常使用，讀寫真實數據；內容管理員只看到 Characters 和 IPs；預覽頁和規劃頁只有超級管理員看到，並有橫幅寫明示例數據、按鈕不能用；每頁有 #hash 可直接打開；手機寬度沒有橫向捲動。
A31: P2-24 | B31: 麥克風上行改用 IMA ADPCM（減少 4 倍頻寬） | C31: 2 內測準備 | D31: 進行中 | E31: 上次測試：部分通過 — ① pytest test_mic_adpcm 10 項：Mac 上編譯 firmware MicAdpcm.cpp，與 audioop 逐 byte 一致（改壞一個表值即失敗）；分塊解碼 = 連續流解碼；掉一塊只損失該塊；人聲段 SNR > 20dB；全套 275 passed ② 伺服器按 X-Mic-Codec 解碼，無 header 照舊 PCM（10:37 1.7.5 → mic=pcm，10:40 1.7.6 → mic=adpcm）③ 62:70 Guest（2026-10-15）：ADPCM 3 輪 Azure zh-HK 辨識通順完整（如『但係點解依家望到外邊係陰天嘅？』），STT 431–526ms，對照同場 PCM 560ms；上行 27,650B/3,370ms 與 16,625B/2,026ms = 8.2 B/ms（PCM 32），發送最長 3ms、最低 heap 55KB ① 新韌體上行用 IMA ADPCM（64 kbps），每幀帶解碼狀態（預測值＋步長索引），掉幀或重連後下一幀即可正確解碼 ② 連線時以 header 聲明編碼；伺服器據此解碼成 16kHz PCM 再交給 STT；沒有聲明的舊韌體照舊當 PCM ③ 韌體編碼與伺服器解碼位元一致（同一算法）④ 編碼 CPU < 2%、不增加延遲 ⑤ 語音辨識品質與 PCM 相當
... A42: R-25 | B42: 網頁的品牌主題系統 | C42: 2 內測準備 | D42: 未開始 | E42: ① 每個品牌一個資料夾：主題 token（顏色、字體、圓角）、logo 和圖示、文案、功能開關；首頁、上手流程、角色頁可以有品牌版本，其餘頁面共用 ② 由部署的環境變數選品牌（每套部署一個品牌，見 R-34），伺服器端渲染的第一屏就是對的主題，不閃爍 ③ 共用元件裡沒有品牌名稱和寫死的品牌顏色 ④ 加一個品牌只需要加資料夾、設定和一套部署，不用改共用元件
A44: ✅ 最近完成與測試效果
A45: 編號 | B45: 任務 | C45: 測試結果 | D45: 完成日期 | E45: 測試證據
A46: P2-21 | B46: P2-16 ⑤ 後台 OTA 頁換成真實數據與操作 | C46: 通過 | D46: 2026-10-15 | E46: 10-14 模擬 20 台全部通過（見上次）；2026-10-15 真機補做：OTA 頁對 1.7.1 白名單加 62:70（UI MAC 欄）→ 存檔確認框 → 『Narrow to Whitelist』確認 → Make current（用戶點）→ 62:70 安裝並確認，頁面顯示 Rolling out · Whitelist、運行 1、回滾 0；每步一筆審計。依賴 P2-14 已完成
A47: P2-16 | B47: OTA 分批推送與後台發佈頁 | C47: 通過 | D47: 2026-10-15 | E47: ④ 真機 62:70（2026-10-15）：USB 刷 1.7.0（開機印 aibuddy-build;kind=dev;…;version=1.7.0）→ release_firmware.py publish --dev 1.7.1 → 後台白名單加 62:70、改白名單階段、設為 current → 按 BOOT 喚醒：取 token 200、下載 12.8s、重開進 app1，09:39:36 連上語音伺服器；09:42 重開 → 『Firmware 1.7.1 on app1』無 probation、Up to date；頁面『Rolling out · Whitelist』運行 1 台、回滾 0；審計 5 筆（發佈、白名單、階段、1.6.2 取消 current、1.7.1 設 current）。①②③⑤ 見 P2-17～P2-21 模擬 20 台
A48: P2-14 | B48: Admin 設備頁：每台玩具的狀態、韌體與基本操作 | C48: 通過 | D48: 2026-10-15 | E48: 真機 62:70（2026-10-15，分支 hw-test-1015 = dev+P2-16，-localall 1.7.0，本機網頁 3230 + 語音 7870）：① 開機 → 設備頁 Online、-67 dBm、1.7.0；板子停在 bootloader 約 38 秒後語音伺服器判離線（uvicorn ping 超時），頁面 0 台在線 ② 重置設備密鑰 → device_secrets 行刪除，板子重開印『Device secret issued and stored』並連上，行恢復 ③ 強制解綁 → 板子拿 202（配對碼 UKDM7N），語音伺服器拒絕連線；兩項審計各 1 筆含操作者與原因 ④ 內容管理員/anon → 42501（10-14 探測腳本）
A49: P2-20 | B49: P2-16 ④ 從後台上傳與發佈韌體（取代手貼 service key） | C49: 通過 | D49: 2026-10-14 | E49: node --test lib/firmwareImage.test.mjs 8/8（合成映像：dev build、無標記、未知板、晶片不符、非映像、截斷/損壞、超 4MB 拒；超 2MB 只警告）。分支 dev server + 本機 Supabase 端到端 16/16（GoTrue 真實登入的 cookie）：超管上傳 9.9.0 release build → 201 草稿（is_current f、rollout 0%），DB SHA-256 = 檔案、storage 原樣；審計 insert 記該超管；設備仍只拿到 current 1.6.2；已有 1.0.2 → 409；localall → 422 dev build；4MB+16 → 422；9MB → 413；PNG → 422；舊 1.6.1 映像（無標記）→ 422 指向 release_firmware.py；內容管理員上傳/刪除 → 403；未登入 → 401；刪 current → 409；超管刪草稿 → 行和映像都刪、審計 delete 記該超管。release_firmware.py list 照常。測試帳號與數據已清除
A50: P2-19 | B50: P2-16 ③ 回滾過多時自動暫停推送 | C50: 通過 | D50: 2026-10-14 | E50: migration 20261014200000 BEGIN/ROLLBACK 套用兩次無錯並已套用本機。模擬 20 台連跑兩次 12/12：1/20 回滾不暫停、其餘 18 台照常；2/20 → 'Auto-paused: 2 of 20 boards rolled back (10%)'，其餘 0 台拿到 ota；已運行的設備記為 running 且不再下發；審計 1 筆 actor 空；恢復後 17 台拿到、保持恢復，第 3 台回滾 → 'Auto-paused: 3 of 20 (15%)'；白名單 2 台中 1 台回滾 → 50% 立即暫停、另一台不再下發；anon 呼叫 ota_maybe_pause → 401/42501。測試數據已清除，spotpear-ai-toy 1.6.2 仍 100% 未暫停
A51: P2-18 | B51: P2-16 ② 按 MAC 雜湊穩定分組決定哪台收到 ota | C51: 通過 | D51: 2026-10-14 | E51: node --test lib/otaRollout.test.mjs 6/6：10,000 隨機 MAC 在 10%/50% 誤差 < 1 個百分點、同 MAC（含大小寫/空白）結果一致、升階段只增不減、白名單各階段都在、不同版本選不同的 10%。tsc --noEmit 通過。分支 dev server（3216）+ 本機 Supabase 模擬 20 台（板型 p218-sim，連跑兩次 9/9）：白名單階段只有 1 台、重複不變；10% 拿到的正是雜湊預測的那組（2–5 台含白名單），重複不變；50% 包含 10% 全部；暫停 → 0 台且下載映像 404，恢復 → 200；100% → 除已更新和已回滾的 2 台外 18 台；每台下發次數與記錄一致；運行中/已回滾正確標記；審計 6 筆對應 6 次變更。真 spotpear-ai-toy（預設 100%）回報 1.6.1 → 仍拿到 1.6.2。測試數據已清除
A52: P2-17 | B52: P2-16 ① 分批推送的數據表：推送階段、白名單、每台安裝結果 | C52: 通過 | D52: 2026-10-14 | E52: migration 20261014190000 BEGIN/ROLLBACK 套用兩次無錯並已套用本機；行為：預設 100%、promote 記 stage_changed_at，7 種壞值（25%、小寫/空字串/NULL MAC、暫停缺原因等）全被 check 擋；ota_note_offer 1→2→3，report 正確標 running/failed、別板型不影響，刪發佈連帶刪記錄；審計 5 筆含 'test-board 9.9.9' 標籤。REST 13/13：超管可讀、內容管理員 0 行、anon 42501，三種身份寫入/改階段/呼叫 ota_note_offer 皆 42501。release_firmware.py promote spotpear-ai-toy 1.6.2 成功，token 查詢仍選 1.6.2，審計記 2 筆（actor 空＝service role）
A53: R-41 | B53: App 顯示玩具電量狀態（低電量提示） | C53: 通過 | D53: 2026-10-14 | E53: ① pytest 33 passed；真 PATCH 本地 Supabase ② 62:70 刷 p212+R-41 強制低電 build（SUPPLY_LOW_RATIO_OVERRIDE=1.05）→ 串口 [WSc] power low:true，本地 DB battery_low=t ③ 刷回正常 1.6.2 → low:false，DB=f ④ App 讀 DB：低電紅標+Please charge+更新時間、72% 充電中、未上報不顯示 ⑤ 他人帳號 0 行、authenticated UPDATE 被拒。62:70 已還原為原 p212 build
A55: ⏳ 等待依賴 / ⛔ 阻塞
...

Sheet 任務清單
A1: 編號 | B1: 優先級 | C1: 階段 | D1: 類別 | E1: 任務 | F1: 狀態 | G1: 測試結果 | H1: 完成日期 | I1: 問題 / 風險 | J1: 相關位置 | K1: 驗收標準 | L1: 測試方法 | M1: 依賴 | N1: 測試證據 | O1: Commit | P1: 備註
A2: P0-01 | B2: P0 | C2: 1 止血定案 | D2: 安全-驗證 | E2: 確認線上環境的暴露面 | F2: 不適用 | G2: 未測試 | I2: 本機 supabase_db_ElatoAI 已確認 RLS 全開、anon 擁有敏感表的全部權限；線上 elatoai.hkqft.com 尚未驗證，它決定 P0 要多急。 | J2: https://elatoai.hkqft.com/supabase-api frontend-nextjs/app/api/generate_auth_token/route.ts | K2: 取得用戶批准後做只讀探測，逐項記錄 P0-02、P0-03、P0-04、P0-06 在線上是否成立。 | L2: 用 anon key 對 /supabase-api/rest/v1/{conversations,users,devices} 發 HEAD 請求並帶 Prefer: count=exact，只看 Content-Range 的總數，不讀任何內容。 | P2: 探測線上必須先得到用戶在對話中明確批准。 [2026-09-30] Q2：目前沒有真實家庭使用，緊急度已確定；線上驗證改為每項修復部署後各自做。
A3: P0-02 | B3: P0 | C3: 1 止血定案 | D3: 安全-資料庫 | E3: 收緊 conversations 表的 RLS | F3: 已完成 | G3: 通過 | H3: 2026-10-12 | I3: policy「PUBLIC conversations」對所有角色 ALL USING(true)：任何拿到前端 anon key 的人都能讀、改、刪所有孩子的對話記錄。 | J3: supabase/migrations/20250417155518_remote_schema.sql:404 server/fastapi/memory/store.py:310 | K3: 刪除該 policy；authenticated 只能 SELECT／DELETE 自己 user_id 的行；寫入只經 service_role；anon 無任何存取。 | L3: ① 本機 psql 查 pg_policies，conversations 沒有 qual=true 的 policy ② 用 anon key 呼叫 REST 讀取，回傳 0 行 ③ 用戶 A 的 JWT 讀不到用戶 B 的對話 ④ 跑一次語音對話，新行照常寫入 | N3: 線上 2026-10-12（bac24e9）：用網站 bundle 裡的 anon key GET conversations/memory_facts/memory_segments/memories → 42501；10/08 runbook 伺服器端檢查：anon 無授權、無 USING(true)、無管理員 policy 觸及記憶表，25/25 通過；authenticated 分戶隔離沿用本機實測 | O3: e3dfb35 | P3: [2026-10-07] 2026-10-07：migration 20261007130000_lock_down_users_devices_conversations.sql 已寫好並在本機驗證通過，尚未提交。上線順序：先部署新前端（舊前端在新規則下無法建新用戶、無法認領）→ 再在線上 docker exec psql -1 套用 migration → 用線上前端實際的 anon key 重跑 anon GET/PATCH，通過後才標完成。 [2026-10-07] 2026-10-07：用戶決定延後部署，與後續任務合併成一批上線。mygithub/main 與 GHCR :latest 已是新版（da98048 起），主機在跑 runbook 前不可 docker compose pull。
A4: P0-03 | B4: P0 | C4: 1 止血定案 | D4: 安全-資料庫 | E4: 收緊 users 表的 RLS | F4: 已完成 | G4: 通過 | H4: 2026-10-12 | I4: 「Update user table」允許 anon UPDATE 任何用戶；「Enable read access for all users」讓任何人讀取全部用戶（email、孩子姓名、年齡、個性描述）。 | J4: supabase/migrations/20250417155518_remote_schema.sql:392, :408 | K4: 移除 anon UPDATE 與公開 SELECT；用戶只能讀、改自己那一行；service_role 不受影響。 | L4: ① anon GET /rest/v1/users 回傳 0 行 ② anon PATCH 失敗 ③ 用戶 A 讀不到用戶 B ④ Web 設定頁保存孩子資料正常 | N4: 線上 2026-10-12（bac24e9）：anon GET users → 42501；anon PATCH users（不存在的 user_id）→ 42501 permission denied；runbook 伺服器端 anon 無授權、無 USING(true)；分戶讀改沿用本機實測 | O4: e3dfb35 | P4: [2026-10-07] 2026-10-07：migration 20261007130000_lock_down_users_devices_conversations.sql 已寫好並在本機驗證通過，尚未提交。上線順序：先部署新前端（舊前端在新規則下無法建新用戶、無法認領）→ 再在線上 docker exec psql -1 套用 migration → 用線上前端實際的 anon key 重跑 anon GET/PATCH，通過後才標完成。 [2026-10-07] 2026-10-07：用戶決定延後部署，與後續任務合併成一批上線。mygithub/main 與 GHCR :latest 已是新版（da98048 起），主機在跑 runbook 前不可 docker compose pull。
A5: P0-04 | B5: P0 | C5: 1 止血定案 | D5: 安全-資料庫 | E5: 收緊 devices 表的 RLS | F5: 已完成 | G5: 通過 | H5: 2026-10-12 | I5: 任何人可 SELECT 全部設備（含 MAC），也可 UPDATE 任何設備：改掉 user_id 就能把別人的玩具綁到自己帳號。 | J5: supabase/migrations/20250417155518_remote_schema.sql:381, :421 | K5: 只有擁有者可讀自己的設備；認領、解綁改走 server action + service_role；anon 無存取。 | L5: ① anon GET /rest/v1/devices 回傳 0 行 ② anon PATCH user_id 失敗 ③ Web 端認領、解綁、調音量流程正常 | N5: 線上 2026-10-12（bac24e9）：anon GET devices/device_secrets → 42501；anon PATCH devices（不存在的 user_id）→ 42501；認領／解綁網頁流程沿用本機實測 | O5: e3dfb35 | P5: [2026-10-07] 2026-10-07：migration 20261007130000_lock_down_users_devices_conversations.sql 已寫好並在本機驗證通過，尚未提交。上線順序：先部署新前端（舊前端在新規則下無法建新用戶、無法認領）→ 再在線上 docker exec psql -1 套用 migration → 用線上前端實際的 anon key 重跑 anon GET/PATCH，通過後才標完成。 [2026-10-07] 2026-10-07：用戶決定延後部署，與後續任務合併成一批上線。mygithub/main 與 GHCR :latest 已是新版（da98048 起），主機在跑 runbook 前不可 docker compose pull。
A6: P0-05 | B6: P0 | C6: 1 止血定案 | D6: 安全-資料庫 | E6: 撤銷敏感表的多餘授權 | F6: 已完成 | G6: 通過 | H6: 2026-10-12 | I6: anon 與 authenticated 對 users／devices／conversations 擁有 TRUNCATE、DELETE、UPDATE 等全部權限；RLS 只要寫錯一條就全面失守。 | J6: information_schema.role_table_grants（本機已查證） | K6: anon 對這三張表沒有任何權限；authenticated 只保留必要權限，沒有 TRUNCATE。 | L6: psql 查 information_schema.role_table_grants：anon 對三張表沒有記錄，authenticated 沒有 TRUNCATE。 | N6: 線上 2026-10-12（bac24e9）：anon 對 users/devices/conversations 等 10 張私人表 GET 全部 42501（授權層拒絕）；runbook psql：role_table_grants anon=0；authenticated 權限沿用本機 role_table_grants 實測 | O6: e3dfb35 | P6: [2026-10-07] 2026-10-07：migration 20261007130000_lock_down_users_devices_conversations.sql 已寫好並在本機驗證通過，尚未提交。上線順序：先部署新前端（舊前端在新規則下無法建新用戶、無法認領）→ 再在線上 docker exec psql -1 套用 migration → 用線上前端實際的 anon key 重跑 anon GET/PATCH，通過後才標完成。 [2026-10-07] 2026-10-07：用戶決定延後部署，與後續任務合併成一批上線。mygithub/main 與 GHCR :latest 已是新版（da98048 起），主機在跑 runbook 前不可 docker compose pull。
A7: P0-06 | B7: P0 | C7: 1 止血定案 | D7: 安全-認證 | E7: 停止憑 MAC 發放永久用戶 JWT | F7: 已完成 | G7: 通過 | H7: 2026-10-12 | I7: /api/generate_auth_token 只憑 MAC 就發出 role=authenticated、sub=家長 user_id、沒有過期時間的 JWT；配合 P0-04 讀到的 MAC 清單，可以接管所有家長帳號。 | J7: frontend-nextjs/app/api/generate_auth_token/route.ts:195 | K7: 設備首次連線時一次性下發設備密鑰；之後用密鑰換短期（≤24 小時）設備 token，權限只限設備本身，不再是家長 session。 | L7: ① 只知 MAC 的請求拿不到任何 token ② 過期 token 被拒 ③ 設備 token 讀不到 users／conversations ④ 實機配對、對話端到端正常 | N7: 線上 2026-10-12（bac24e9）：POST /api/generate_auth_token 只帶 42:34 的 MAC → 401、帶錯誤密鑰 → 401、GET → 410；42:34 用 NVS 密鑰在線上換 token 並連上語音伺服器（P0-13 10/09 實測） | O7: da98048 | P7: [2026-10-07] 2026-10-07：實作＝device_secrets 表（20261007150000）＋lib/deviceAuth.ts＋generate_auth_token 改 POST＋韌體密鑰存 NVS「device」、token 只放 RAM、斷線時續期。上線必須三者一起：前端、語音伺服器、韌體；兩邊 env 都要先設同一個 DEVICE_JWT_SECRET；雲端已配對的測試板要重燒。NVS 被清的板子要刪 device_secrets 那行才能重新領密鑰。 [2026-10-07] 2026-10-07：本機全部驗收通過（commit da98048），仍保持進行中：線上尚未部署。上線順序：兩邊 env 設同一個 DEVICE_JWT_SECRET → 套用 20261007150000 → 部署前端與語音伺服器 → 重燒雲端測試板。 [2026-10-07] 2026-10-07：用戶決定延後部署，與後續任務合併成一批上線。mygithub/main 與 GHCR :latest 已是新版（da98048 起），主機在跑 runbook 前不可 docker compose pull。
A8: P0-07 | B8: P0 | C8: 1 止血定案 | D8: 安全-認證 | E8: 輪換 JWT secret，作廢已發出的 token | F8: 進行中 | G8: 未測試 | I8: 已發出的 token 永不過期，只能換 secret 作廢；自架 Supabase 的 anon／service_role key 也由同一個 secret 簽發，會一起失效。 | J8: 伺服器上自架 Supabase 的 .env 前端與 FastAPI 的 env | K8: ① 生產自架 Supabase 換上新的 JWT secret（app.settings.jwt_secret 一併更新），重發 anon／service_role key，更新到 Supabase 各容器、網頁（anon key 要重新建置 image）和語音伺服器。② 用舊 secret 簽的東西全部失效：舊 anon key、舊 service_role key、舊 secret 簽的無過期用戶 JWT（P0-06 前 MAC 換到的那種）。③ DEVICE_JWT_SECRET 同時輪換；設備不用重新配對（P0-06 之後設備靠 NVS 裡的設備密鑰自動換新 token）。④ 沒有任何運行中的容器還持有舊值；用到 service key 的其他地方（例如 Mac 上的 release_firmware.py）已改用新 key。⑤ 有回滾方法。 | L8: 照 docs/deploy/rotate-2026-10-jwt-secrets.sh 在伺服器執行，第 6 步自動檢查：① 舊 anon key、舊 service_role key、舊 secret 簽的 canary 用戶 JWT（第 3 步證明輪換前可用）→ 401 ② 新 anon／service key → 200；網站 JS 只含新 anon key；generate_auth_token 新設備 → 202；語音伺服器拒絕舊 device token、接受新的；輪換後已綁定設備自動回來（last_seen_at 更新）③ 運行中容器的環境變數裡沒有任何舊值 ④ 人手：網頁登入、playground 對話、實機對話各一次 | M8: P0-06 | P8: [2026-10-12] 2026-10-12：runbook 已寫好（分支 p0-07-rotate-secrets）。輔助函數本機測試 18/18：自簽 JWT 能被 node jsonwebtoken 驗證、語音伺服器 device_auth.verify 接受新 token、拒絕簽錯的 token、env 檔替換正確。驗收從「所有設備重新配對」改為「設備不用重新配對」，因為 P0-06 之後設備靠設備密鑰自動換 token。下一步：用戶在伺服器跑 STEP=0（只讀）並把結果貼回來。
A9: P0-08 | B9: P0 | C9: 1 止血定案 | D9: 安全-語音伺服器 | E9: 語音伺服器驗證設備身份（/ws/esp32） | F9: 已完成 | G9: 通過 | H9: 2026-10-12 | I9: 只看 X-Device-Mac header，Bearer token 只記進 log、從不驗證；任何人冒充一台玩具就能問出孩子的記憶，並消耗 API 額度。 | J9: server/fastapi/server.py:375 | K9: 驗證設備 token 的簽名與有效期，設備身份取自 token 而不是 header；無效就以 4401 關閉連線。 | L9: ① 偽造 X-Device-Mac、不帶 token 被拒 ② 過期 token 被拒 ③ 真實設備正常對話 ④ 新增 pytest 覆蓋以上情況 | M9: P0-06 | N9: 線上 2026-10-12（bac24e9）：wss /fastapi/ws/esp32 不帶 token、偽造 token＋X-Device-Mac → 均 4401 invalid device token；42:34 以有效 token 連線對話正常（P0-13 10/09） | O9: da98048 | P9: [2026-10-07] 2026-10-07：device_auth.py 用標準庫 hmac 驗 HS256（venv 無 PyJWT），每次呼叫才讀 DEVICE_JWT_SECRET（bot.py 的 load_dotenv 在 import 之後）。未設 secret 時所有設備被拒。 [2026-10-07] 2026-10-07：本機全部驗收通過（commit da98048），仍保持進行中：線上尚未部署。上線順序：兩邊 env 設同一個 DEVICE_JWT_SECRET → 套用 20261007150000 → 部署前端與語音伺服器 → 重燒雲端測試板。 [2026-10-07] 2026-10-07：用戶決定延後部署，與後續任務合併成一批上線。mygithub/main 與 GHCR :latest 已是新版（da98048 起），主機在跑 runbook 前不可 docker compose pull。
A10: P0-09 | B10: P0 | C10: 1 止血定案 | D10: 安全-語音伺服器 | E10: 瀏覽器語音路由改用簽名 token（/ws/nextjs） | F10: 已完成 | G10: 通過 | H10: 2026-10-12 | I10: user_id 和角色 prompt 都取自 query string：知道某個 user_id 就能讀到那個孩子的記憶，也能注入任意角色 prompt。 | J10: server/fastapi/server.py:316 | K10: Next.js 為已登入用戶簽發 ≤5 分鐘的 token，FastAPI 驗證後才取 user_id；角色與 prompt 由伺服器端按帳號讀取。 | L10: ① 改 query 裡的 user_id 無效 ② 不帶 token 被拒 ③ Web 對話與記憶正常 | N10: 線上 2026-10-12（bac24e9）：wss /fastapi/ws/nextjs 只帶 user_id 或 token=bogus → 4401；用戶確認：登入 elatoai.hkqft.com 後網頁 playground 可正常對話 | O10: af99fdf | P10: [2026-10-07] 2026-10-07：沿用 DEVICE_JWT_SECRET，以 aud/typ 區分。網頁與語音伺服器須同時上新版。保持進行中：隨下一批部署後線上複測。
A11: P0-10 | B11: P0 | C11: 1 止血定案 | D11: 安全-語音伺服器 | E11: 生產環境關閉 /browser 測試頁與 /ws/browser | F11: 已完成 | G11: 通過 | H11: 2026-10-12 | I11: 完全開放：任何人都能免費使用你付費的 STT／LLM／TTS。 | J11: server/fastapi/server.py:264, :286 | K11: 預設關閉；只有顯式設定開關（例如 ENABLE_BROWSER_TEST=true）時才註冊這兩個路由。 | L11: 生產配置下 GET /browser 回 404，連線 /ws/browser 被拒。 | N11: 線上 2026-10-12（bac24e9）：GET /fastapi/browser 404、/fastapi/ 404、/fastapi/healthz 200、wss /fastapi/ws/browser → HTTP 403 | O11: d0cfbb8 | P11: [2026-10-07] 2026-10-07：本機 server/fastapi/.env 加 ENABLE_BROWSER_TEST=true 方便開發；線上不設。保持進行中：要隨下一批部署後在線上複測（GET https://elatoai.hkqft.com/fastapi/browser → 404）。
A12: P0-11 | B12: P0 | C12: 1 止血定案 | D12: 安全-認證 | E12: 設備認領要求持有證明 | F12: 進行中 | G12: 部分通過 | I12: 任何登入用戶都能看到全球 10 分鐘內上線的未認領設備並直接認領；202 回應把配對碼交給任何知道 MAC 的人。 | J12: frontend-nextjs/db/devices.ts:62 frontend-nextjs/app/api/generate_auth_token/route.ts:172 | K12: 綁定票（用戶 2026-10-12 決定，經藍牙交付，見 R-21）：① 已登入的 App 向伺服器取綁定票：一次性、5 分鐘有效，綁定該帳號和品牌。② 設備連上 Wi-Fi 後，用設備密鑰加綁定票呼叫伺服器；伺服器在同一個交易裡檢查票有效、設備 user_id 為空、品牌相符，然後寫入 user_id 和 claimed_at，並把票作廢。③ 不再列出全球未認領設備，也不再用手動輸入的配對碼認領（舊流程只在開發模式保留）。④ 已有主人的設備不能被認領：原主在 App 內解綁，聯絡不到原主就由管理員在後台解綁（R-11）。⑤ 第一版一台設備只屬一個帳號。⑥ 取票有頻率上限（每帳號每分鐘 5 次）。 | L12: ① 只知 MAC 或 user_code 不能認領 ② 綁定票過期、用過一次、屬於另一品牌 → 認領被拒 ③ 帳號 B 的票交給 A 已綁定的設備 → 被拒，A 的綁定不變 ④ 沒有設備密鑰只帶票 → 401 ⑤ 正常流程：simulate_device.py 帶有效票 → 200 token，devices.user_id 和 claimed_at 寫入 ⑥ 設定頁不再出現別人的未認領設備 ⑦ 取票超過頻率上限 → 429 | M12: P0-06 | N12: 本機（分支 p0-11-bind-ticket da3709b，localhost:3015 + 本機 Supabase，測試腳本 22/22）：① 只帶 MAC → 401、密鑰 + user_code 當票 → 403 且設備仍無主 ② 票用過（另一台）／過期／本庫沒發過的票（他品牌）→ 403 ③ B 的票交給 A 的設備 → 409 device_owned，A 綁定不變、B 的票未作廢 ④ 有效票但無設備密鑰 → 401、票未作廢 ⑤ 密鑰 + 有效票 → 200 token，user_id 和 claimed_at 寫入；同一台重送同一張票 → 200 ⑥ DEVICE_CLAIM_LIST=False 時設定頁沒有未認領清單和配對碼欄，有未認領設備在線也看不到，12 秒內無輪詢；=True 時開發清單照舊可認領 ⑦ 同帳號並行 10 次取票 → 5×200、5×429，B 不受影響，滿一分鐘後恢復；表只存 SHA-256；authenticated 讀表／呼叫 RPC → 42501。未部署線上。 | O12: da3709b | P12: [2026-10-07] 2026-10-07：addUserToDevice（輸入配對碼）沒有限制 user_id IS NULL，知道配對碼就能把已有主人的設備轉到自己帳號；P0-04 只把它搬到 service_role，行為未改，留給本項處理。 [2026-10-07] 2026-10-07：P0-06 之後配對碼只回給持有設備密鑰的請求（只知 MAC → 401），驗收第一條在本機已成立；仍缺：不再列出全球未認領設備、輸錯上限、addUserToDevice 搶已綁定設備。 [2026-10-12] 2026-10-12 用戶確認綁定設計：Spotpear 沒有螢幕、也不讀出配對碼（韌體只印在序列埠），所以改為配網時綁定；已有主人的設備要原主先解綁，否則找客服；第一版一台設備只屬一個帳號。現況漏洞仍在：設定頁列出全球未認領設備可直接認領（AppSettings.tsx、getUnclaimedDevices）；addUserToDevice 沒有檢查 user_id IS NULL，也不寫 claimed_at。 [2026-10-12] 2026-10-12 再改：用戶決定用藍牙配網（R-21），不用熱點綁定碼。改為「App 取綁定票，經藍牙交給設備，設備自己認領」，本項只管伺服器端，不用等藍牙就能先做和測試。 [2026-10-12] 伺服器端完成並在本機全部通過，未部署。注意：DEVICE_CLAIM_LIST 在生產預設關閉，部署後網頁不能再加新設備，要等 R-21 藍牙配網（或臨時在生產開 DEVICE_CLAIM_LIST）。分支以 mygithub/main（8db9d9c）為基礎；本機 main 落後且沒有 P1-12。 [2026-10-12] 2026-10-12 用戶決定：P0-11 不單獨部署，等 R-21 藍牙配網做好後一起上線，避免生產網頁在中間這段時間不能加新設備。
A13: P0-12 | B13: P0 | C13: 1 止血定案 | D13: 安全-Web | E13: 收緊 Admin 權限與路由保護 | F13: 已完成 | G13: 通過 | H13: 2026-10-12 | I13: 沒設 ADMIN_EMAILS 時所有登入用戶都是管理員，可以改全站模型、讀寫別人孩子的角色 prompt；middleware 的登入保護被註解掉。 | J13: frontend-nextjs/lib/admin.ts:45 frontend-nextjs/utils/supabase/middleware.ts:42 | K13: ① 用 admin_roles 表（user_id、角色、授權人、時間）和資料庫函數 has_role() 取代 ADMIN_EMAILS；v1 只有兩種角色：超級管理員、內容管理員 ② 管理端在 /admin：middleware 擋未授權的路由，每個 server action 再檢查一次角色，資料庫 RLS 也用 has_role() 把關。不要求兩步驗證 ③ 任何管理員角色在資料庫層面都沒有讀取其他家庭 conversations、memory_facts、memory_segments 的權限 ④ 恢復 middleware 對 /home 的登入保護 | L13: ① 普通家長帳號訪問 /admin 被拒；直接呼叫 admin server action 被拒 ② 內容管理員能改角色，不能改模型設定和管理員名單 ③ 用超級管理員的 JWT 查 conversations、memory_facts、memory_segments，讀不到其他家庭的資料 ④ 未登入訪問 /home 跳到 /login | N13: 線上 2026-10-12（bac24e9）：runbook 10/08 檢查 未登入 /admin→/login、/api/admin→401、has_role() 只看角色、無管理員 policy 觸及 conversations/記憶表、超管≥1；未登入 /home、/admin→/login；用戶確認：家長帳號開 /admin 轉回 /home、管理員在 /admin 修改角色保存成功；角色細分權限沿用本機 61/61 | O13: c16e1c2 | P13: [2026-09-30] 權限設計討論後擴大範圍：見 Q7、Q9 [2026-10-07] 2026-10-07 本機驗證通過，未部署。上線前：生產 GoTrue 開 TOTP（GOTRUE_MFA_TOTP_ENROLL/VERIFY_ENABLED=true）、套 20261007140000+180000、手動 INSERT 第一個 super_admin；P0-17（anon key 是否 secret）未解前 ④ 在生產不成立 [2026-10-07] 2026-10-07 用戶決定取消 TOTP：管理員只看帳號角色，登入後可直接進 /admin。has_role() 不再要求 aal2（20261007191000）。 [2026-10-07] 2026-10-07 c16e1c2 取消 TOTP 後重測通過。未部署：上線時 runbook 會套 20261007191000 並檢查 has_role() 不含 aal；生產 GoTrue 不再需要開 TOTP。本機 GoTrue 仍開著 TOTP（config.toml 已改，要 supabase stop/start 才生效），不影響權限
A14: P0-13 | B14: P0 | C14: 2 內測準備 | D14: 安全-韌體 | E14: 讓 OTA 真正可用並能回滾 | F14: 已完成 | G14: 通過 | H14: 2026-10-09 | I14: OTA 的韌體 URL 與伺服器證書仍是佔位符：出貨後無法修補任何漏洞。 | J14: firmware-arduino/src/OTA.cpp:9, :14 | K14: 填入真實 URL 與 CA；新韌體啟動自檢通過才標記有效，否則自動回滾；設備上報韌體版本。 | L14: ① 實機推一次升級成功 ② 推一個會崩潰的韌體，確認自動回滾到舊版 | N14: 生產雲端 HTTPS OTA（2026-10-09）：release_firmware.py publish spotpear-ai-toy --current → 1.0.1 現行；42:34 開機 1.0.0 → token 回應 Installing 1.0.1 (1655776 bytes) → 經 Cloudflare+nginx 下載 100% → 重啟到 app1 on probation → 連上語音伺服器 → 120s 後『Firmware 1.0.1 confirmed』。②崩潰回滾沿用 10-08 開發板實測（1.2.2/1.5.3 回滾、1.5.2 切回舊槽）；本機 63:64 1.5.1→1.6.1 亦確認 | O14: 036c0f9 | P14: [2026-10-08] 2026-10-08 b27cc07（分支 p0-13-ota）。部署時要套 20261008100000_firmware_releases.sql，發佈要用 SUPABASE_URL+service key 跑 tools/release_firmware.py [2026-10-08] 2026-10-08 實機①②通過，未部署。上線要：套 20261008100000、部署前端、用 release_firmware.py 發佈正式 build；生產 HTTPS（同 CF CA）的 1.6MB 下載尚未在線上驗證。開發板現跑 1.2.1 localall。未做：已確認版本日後若崩潰循環不會自動切回舊槽，需 USB 救（可另立任務） [2026-10-08] 2026-10-08 OTA 檢查併入 /api/generate_auth_token（68b9550），開機回到一次 TLS 握手；/api/ota/check 移除。token 路徑 API 11/11（舊韌體無 ota、格式錯仍發 token、回滾版本不再提供）；實機 1.3.0→1.3.1 經 token 回應安裝、試用、播完開場白、120s 確認。第一次升級 1.3.1 被 async_tcp 任務看門狗觸發重啟並正確回滾——是既有韌體 bug，見新任務 [2026-10-08] 2026-10-08 交板前強化（682f3b4）：① 確認後連續崩潰 3 次 → 切回另一槽位（每段崩潰期一次）、立即重新確認、上報失敗 ② 回滾按重啟原因判定：崩潰/看門狗即失敗，斷電等非崩潰原因可重試 2 次（R-17 會自己斷電）。實機 1.5.x：試用期內 EN 重啟 → 重試第 2 次並確認；1.5.2 確認後崩潰 3 次 → 回 1.5.1、重新確認、報失敗；1.5.3 試用期崩潰 → 回滾、reason 4 即報失敗。runbook 已加 20261008100000 與 OTA 檢查（3aa632a）。上線後須用開發板對雲端走一次 HTTPS OTA 再交板 [2026-10-09] 2026-10-09 上線前兩個阻礙已修：① Cloudflare 對 Python-urllib UA 回 403 error 1010 → release_firmware.py 自帶 User-Agent（036c0f9）② 主機 nginx /supabase-api/ 預設 1MB 上限 → 413，已在 /home/jackylee/nginx/conf.d/elatoai.conf 兩段 location 加 client_max_body_size 16m（備份 ~/nginx/elatoai.conf.2026-10-09.bak）。雲端此前沒有任何 Spotpear release。service key 只在伺服器 .env.production
A15: P0-14 | B15: P0 | C15: 3 封閉內測 | D15: 安全-韌體 | E15: 韌體簽章、Secure Boot 與 Flash 加密 | F15: 未開始 | G15: 未測試 | I15: 韌體沒有簽章驗證；NVS 裡的 token、WiFi 密碼可以用 esptool 直接讀出。 | J15: firmware-arduino/platformio.ini firmware-arduino/partition.csv | K15: 啟用 Secure Boot v2、flash encryption、NVS encryption；OTA 只接受簽名映像。 | L15: ① 未簽名映像 OTA 被拒 ② esptool read_flash 讀出的是密文 | M15: P0-13, R-01 | P15: 燒 eFuse 不可逆：先用一片測試板驗證，每一步都要用戶確認。 [2026-09-30] Secure Boot 要在定案的板子上驗證
A16: P1-01 | B16: P1 | C16: 2 內測準備 | D16: 兒童安全 | E16: 加入內容審核層（輸入與輸出） | F16: 阻塞 | G16: 未測試 | I16: 只靠 prompt 裡的「Be appropriate」，沒有審核；模型經 OpenRouter 路由到開源模型；Azure STT 預設 profanity=raw（因為 masked 會誤殺非英語）。 | J16: server/fastapi/bot.py server/fastapi/voice_pipeline.py server/fastapi/models/stt/azure.py:47 | K16: STT 文字與 LLM 輸出都經審核，尺度按 3–6 歲；命中時換成安全回覆並記錄事件，事件只記類別、時間、角色，不記原文（管理員不能看兒童內容，見 Q7）；首字延遲增加 ≤150ms。 | L16: ① 30 條紅隊句子（暴力、性、自殘、索取個人資料、越獄）全部被攔截或得到安全回應 ② 100 條正常兒童對話誤攔率 <2% ③ 用 turn_metrics 比較前後延遲 ④ 事件表裡找不到任何對話原文 | P16: [2026-09-30] Q5：3–6 歲；Q7：事件不記原文 [2026-10-14] 2026-10-14：審核事件的後台頁拆成 P1-14，等本項完成後做。 [2026-10-14] 2026-10-14 用戶決定：先不定審核服務商，本項暫停。候選：Azure Content Safety（建議，香港區、可在每句回覆說出口前檢查）、OpenRouter 安全模型、OpenAI Moderation、只用本機字詞表。未寫任何程式。
A17: P1-02 | B17: P1 | C17: 2 內測準備 | D17: 私隱 | E17: 日誌移除兒童個人資料 | F17: 進行中 | G17: 部分通過 | I17: 記憶事實原文、孩子姓名等被寫進伺服器日誌。 | J17: server/fastapi/memory/session.py:482, :488 server/fastapi/device_registry.py（logger.info） | K17: 生產日誌只記 ID、長度、類別，不記內容；內容只在 DEBUG 等級輸出，生產不開 DEBUG。 | L17: 跑一次含孩子姓名與寵物名的對話，grep 日誌找不到原文。 | N17: 本機（分支 p1-02-log-pii）：模擬板子跑 3 輪，孩子名 PROBE小明、性格『鍾意恐龍』、記憶『佢有隻狗叫PROBE豆豆』；把對話、回覆、事實切成 47 段搜日誌 → 預設 INFO 0 段；同一流程 LOG_LEVEL=DEBUG → 27 段（證明搜尋有效）。INFO 日誌也無 token。pytest 245 passed（新增 test_log_privacy 6 項：事實/摘要、PostgREST details、OpenRouter flagged_input、非 JSON 回覆、預設 INFO 與 traceback 無變量值）。未做：部署線上並在生產日誌重跑。 | O17: 4214b99
A18: P1-03 | B18: P1 | C18: 3 封閉內測 | D18: 私隱 | E18: 資料保留期限與自動清理 | F18: 未開始 | G18: 未測試 | I18: 對話與記憶永久保存；刪帳號後資料可能殘留。 | J18: conversations、memory_facts、memory_segments、turn_metrics | K18: 定義保留期（例如對話 90 天）；定時清理；家長能一鍵刪除全部資料並級聯刪除。 | L18: ① 插入過期測試資料，跑清理後消失 ② 刪除測試帳號後各表沒有殘留 | P18: [2026-10-09] 解綁時選擇保留的記憶（P1-12）沒有設備綁定，也要納入保留期限，例如帳號沒有設備且 12 個月沒活動就清除。 [2026-10-09] 補充（2026-10-09 晚）：記憶改成跟設備後，解綁時保留的記憶掛在已解綁的設備名下，家長在設定頁看不到也清不了；還有 device_id 為 NULL 的舊記憶（沒有設備的帳號）。兩者都要納入保留期限自動清理。
A19: P1-04 | B19: P1 | C19: 3 封閉內測 | D19: 合規 | E19: 家長同意流程與私隱政策 | F19: 未開始 | G19: 未測試 | I19: 沒有可驗證的家長同意，也沒有私隱政策；要符合哪條法規取決於目標市場（Q1）。 | J19: frontend-nextjs 註冊／設定流程 | K19: 綁定設備前取得家長同意，並記錄時間與版本；私隱政策列明收集項目、用途、第三方與保留期。 | L19: ① 未同意的帳號無法綁定設備 ② 法律顧問審閱通過 | M19: Q1
A20: P1-05 | B20: P1 | C20: 3 封閉內測 | D20: 合規 | E20: 第三方資料處理協議與資料流向 | F20: 未開始 | G20: 未測試 | I20: 孩子的語音與文字流向 OpenRouter（及其下游模型供應商）、MiniMax、Azure 等第三方。 | J20: server/fastapi/models/ server/fastapi/env.example | K20: 畫出資料流向圖；每家供應商簽 DPA 或確認條款；OpenRouter 請求只路由到不留存、不用於訓練的供應商。 | L20: ① 文件審閱 ② 抓一次 OpenRouter 請求，確認帶 provider.data_collection="deny" | M20: Q1
A21: P1-06 | B21: P1 | C21: 3 封閉內測 | D21: 授權 | E21: 處理 GPL-3.0 依賴（arduino-audio-tools） | F21: 未開始 | G21: 未測試 | I21: 韌體靜態連結 GPL-3.0 的 arduino-audio-tools：閉源銷售就必須公開整個韌體原始碼。 | J21: firmware-arduino/platformio.ini（lib_deps） | K21: 二選一：韌體以 GPL 開源；或替換成 ESP-IDF I2S 等非 GPL 實作。 | L21: 依賴清單中沒有 GPL 庫，或韌體原始碼已公開。 | M21: Q3
A22: P1-07 | B22: P1 | C22: 3 封閉內測 | D22: 授權 | E22: LGPL 合規與第三方授權聲明 | F22: 未開始 | G22: 未測試 | I22: AsyncTCP、ESPAsyncWebServer（LGPL-3.0）、WebSockets（LGPL-2.1）靜態連結，有讓用戶重新連結的義務；上游 ElatoAI 是 MIT，需要保留聲明。 | J22: firmware-arduino/.pio/libdeps LICENSE | K22: 產出 THIRD_PARTY_NOTICES；提供可重新連結的目標檔，或替換這些庫。 | L22: 文件審閱。 | M22: Q3
A23: P1-08 | B23: P1 | C23: 3 封閉內測 | D23: 硬件 | E23: 硬件認證 | F23: 未開始 | G23: 未測試 | I23: 無線（FCC／CE-RED 等）、玩具安全（EN71／ASTM F963）、電池運輸（UN38.3）都是上市前提，具體取決於目標市場。 | J23: 硬件設計 | K23: 列出目標市場需要的認證清單與時間表，並完成送測。 | L23: 取得認證報告。 | M23: Q1, R-01, R-05 | P23: [2026-09-30] 送測需要定案的板子和外殼樣品
A24: P2-01 | B24: P2 | C24: 1 止血定案 | D24: 測試 | E24: 修好後端測試環境 | F24: 已完成 | G24: 通過 | H24: 2026-10-07 | I24: 129 個測試中 58 個失敗；原因是 dev 依賴缺 pytest-asyncio，不是程式錯誤。 | J24: server/fastapi/pyproject.toml | K24: dev group 加入 pytest 與 pytest-asyncio；全部測試通過。 | L24: cd server/fastapi && .venv/bin/python -m pytest -q 全部通過。 | N24: cd server/fastapi && .venv/bin/python -m pytest -q → 173 passed（原本 60 個 async 測試報「not natively supported」）；pyproject dev group 加 pytest>=9,<10、pytest-asyncio>=1.4,<2，asyncio_mode=auto；pip install --dry-run --group dev 可解析 | O24: 6641fa8 | P24: [2026-10-07] 2026-10-07：pytest-asyncio 其實已裝，問題是 strict 模式略過沒有 marker 的 async 測試。剩 10 個 warning 是 pipecat/fastapi 棄用提示與兩個 memory_processors 測試沒啟動 processor，不影響結果。
A25: P2-02 | B25: P2 | C25: 2 內測準備 | D25: CI/CD | E25: CI 跑測試與靜態檢查 | F25: 未開始 | G25: 未測試 | I25: CI 只 build image，不跑任何測試：壞的程式照樣會發佈。 | J25: .github/workflows/ | K25: 推送與 PR 時跑 pytest、ruff、pyright、next lint、tsc --noEmit、pio run；任何一項失敗就不發佈 image。 | L25: 故意推一個失敗測試到分支：CI 變紅，而且沒有發佈 image。 | M25: P2-01
A26: P2-03 | B26: P2 | C26: 1 止血定案 | D26: 版本管理 | E26: 提交目前未提交的改動 | F26: 已完成 | G26: 通過 | H26: 2026-10-06 | I26: 57 個檔案未提交，包括新板子支援（BoardConfig、Codec、IoExpander、LedRing、Battery），隨時可能遺失。 | J26: git status | K26: 按主題拆成若干 commit 並推到 mygithub。 | L26: git status 乾淨；mygithub 上可以看到這些 commit。 | N26: git status --short → 0 行；3bc7119..b322375 按主題拆成 5 個 commit（50 檔：xmini-c3 電量、facts 記憶層、日期時間天氣、BEAM 評測、進度追蹤）；git ls-remote mygithub main = HEAD = b322375 | O26: b322375 | P26: 推到 mygithub 會觸發部署：推送前先跟用戶確認。
A27: P2-04 | B27: P2 | C27: 2 內測準備 | D27: 部署 | E27: 容器改用非 root 用戶 | F27: 未開始 | G27: 未測試 | I27: FastAPI 與前端容器以 root 運行。 | J27: server/fastapi/Dockerfile frontend-nextjs/Dockerfile | K27: 兩個 Dockerfile 都設定非 root 的 USER。 | L27: docker run --rm <image> id -u 輸出不是 0。
A28: P2-05 | B28: P2 | C28: 4 量產出貨 | D28: 成本/濫用 | E28: 拒絕未知設備並限制用量 | F28: 未開始 | G28: 未測試 | I28: 陌生 MAC 也能拿到預設角色的 session（fail open），可以無限消耗 API。 | J28: server/fastapi/server.py server/fastapi/device_registry.py | K28: 未認證設備拒絕連線；每台設備、每個帳號有每日對話時長上限；每個 IP 有連線限流。 | L28: 超出限額後連線被拒，並留下日誌。 | M28: P0-08
A29: P2-06 | B29: P2 | C29: 3 封閉內測 | D29: 可觀測性 | E29: 錯誤追蹤與告警 | F29: 未開始 | G29: 未測試 | I29: 沒有錯誤追蹤與告警：線上出問題只能靠用戶反映。 | J29: FastAPI、Next.js、韌體（崩潰上報） | K29: 三端接入錯誤追蹤；對健康檢查、錯誤率、延遲 p95 設告警。 | L29: 人為製造一個錯誤，5 分鐘內收到告警。 | P29: [2026-10-12] 2026-10-12：三套獨立部署（R-34），監控集中在一個面板，告警寫明品牌。 [2026-10-14] 2026-10-14：admin 的「系統健康」頁只放摘要和外部監控連結，錯誤追蹤與告警用外部服務，不在後台自己做。
A30: P2-07 | B30: P2 | C30: 3 封閉內測 | D30: 運維 | E30: 資料庫備份與還原演練 | F30: 未開始 | G30: 未測試 | I30: 自架 Supabase，沒看到備份策略：硬碟壞掉就等於失去所有孩子的記憶。 | J30: 伺服器上的自架 Supabase | K30: 每日自動備份到異地，保留 30 天；做過一次完整還原。 | L30: 從備份還原到新實例，核對主要表的行數一致。 | P30: [2026-10-12] 2026-10-12：改為三套獨立部署（R-34），備份和還原演練三套都要做，由同一個腳本循環。
A31: P2-08 | B31: P2 | C31: 4 量產出貨 | D31: 擴展性 | E31: 多實例擴展 | F31: 未開始 | G31: 未測試 | I31: session 登記在進程記憶體裡，只能跑單實例；單機上限未知。 | J31: server/fastapi/server.py:35 server/fastapi/memory/session.py:564 | K31: 壓測得出單機並發上限；需要時按 user_id 做 sticky routing，或把 session registry 移到 Redis。 | L31: ① 壓測報告 ② 兩個實例下，device_refresh 對同一台設備仍然生效 | P31: 優先次序取決於 Q4（第一年設備數量）。
A32: P2-09 | B32: P2 | C32: 2 內測準備 | D32: 成本/濫用 | E32: 每台設備成本監控 | F32: 進行中 | G32: 部分通過 | I32: 不知道每次對話、每台設備每月花多少錢，無法定價。 | J32: turn_metrics 各供應商帳單 | K32: 每個 session 記錄 STT 秒數、LLM token、TTS 字數並換算成本；admin 頁顯示每台設備的月成本。 | L32: 抽 10 個 session 與供應商帳單對帳，誤差 <10%。 | N32: 本機：pytest 239 passed（新增 8 項：STT/TTS 用量入行、遲到的用量帶到下一行、session 結束寫 usage 行、設備 ID、同一輪多次 LLM 相加、記憶整理的 token 即使回覆解析失敗也記錄並記到該設備）。模擬板子跑 2 輪（本機語音伺服器 7865）：送 2.24s 音訊 → stt_audio_ms=2242（兩輪皆是）；每輪有 tts_chars、token、device_id；session 結束的記憶整理寫成 memory 行（deepseek-v4-flash 946/10 token）。Usage 頁按設備與日期顯示 HK$，改費率即重算並進審計。未做：抽 10 個 session 與 Azure/MiniMax/OpenRouter 帳單對帳（需用戶提供帳單）、部署線上。 | O32: 8e3b2c5 | P32: [2026-10-14] 2026-10-14：turn_metrics 目前只記 user_id 和 chat_group_id，沒有設備，也沒有 STT 秒數（只有 transcript_chars／response_chars），要改語音伺服器補上，並加單價表。頁面樣子在 preview/UsagePreview.tsx。內部測試每週要報每台每月成本（R-07），數據只能從開始記錄那天累積，建議 10/30 前做好。 [2026-10-14] 2026-10-14：已合併進 dev（rebase 後 commit 8e3b2c5，原 e438bab）。部署用 docs/deploy/release-2026-10-14-audit-usage.sh：先套兩個 migration，再換語音伺服器和網頁映像；第 5 步自動檢查，第 6 步在跟已綁定的玩具對話後確認用量行。
A33: R-01 | B33: R | C33: 1 止血定案 | D33: 硬件 | E33: 選定量產板子 | F33: 進行中 | G33: 未測試 | I33: 第一批的板子還沒定：Waveshare ESP32-S3-AUDIO-Board 已對線上伺服器跑通完整對話；另一塊類似 xmini-c3 的新板還沒到貨。內測必須用將來量產的那塊板。 | J33: firmware-arduino/BOARDS.md firmware-arduino/src/BoardConfig.h firmware-arduino/src/Config.cpp | K33: 已定案 Spotpear AI Toy（用戶 10/07 決定）；評分表 ①–⑦ 在 Spotpear 上實測並記錄結果，沒有否決性問題（如 2 小時內 OOM 重啟、C3 無法啟用 Secure Boot v2＋Flash 加密、無認證模組）。 | L33: 評分表逐項實測： ① 連續對話 2 小時不重啟、不斷線 ② 對話中最低剩餘 heap 與最大連續塊 ③ 電量讀取與續航（連續對話／待機） ④ 休眠與喚醒 ⑤ 裝殼後喇叭響度、1 米外收音 ⑥ Secure Boot v2＋Flash 加密燒錄流程 ⑦ 500 片價格、交期、FCC／CE 報告、是否已認證模組 ⑧ 加分：螢幕（顯示配對碼）、現成外殼 | P33: 新板到貨前，可先從 xiaozhi-esp32 的 config.h 取腳位預先移植。 [2026-10-05] 2026-10-05：期限由「最遲 10/30」收緊為 10/16，外殼、認證、生產都在等這個決定。 [2026-10-05] 2026-10-05：候選板 toy-ai-core-c3-1.54（ESP32-C3、16MB、無 PSRAM）已到貨並移植，env toy-ai-core-c3，引腳由原廠固件反彙編取得（不在小智官方倉庫），原廠固件已整片備份。實測：開機、ES8311 雙向、喇叭出聲、WS2812 狀態燈、SoftAP；WiFi 開啟後內部 RAM 空閒 73KB／最大塊 53KB（未對話）。評分表尚未測：①②⑤⑥⑦；③原廠固件無電池檢測代碼，可能沒有電池；④本版不休眠；⑧有 1.54 寸 ST7789 屏，本版未驅動。 [2026-10-05] 2026-10-05 補充 toy-ai-core-c3 評分表③：板上已裝電池，但讀不到電量。原廠固件的 GetBatteryLevel 直接 return false；C3 能做 ADC 的腳只有 GPIO0–5，全被屏幕(0/1)、LED(2)、I2C(3/4)、I2S(5) 佔用，所以軟件無法讀電池電壓。要讀電量需改硬件：無屏版可把屏幕的 GPIO0/1 讓出來接分壓電阻，或在現有 I2C 上加電量計（如 MAX17048）。GPIO12/13 尚空，可能接了充電狀態腳，未探測。 [2026-10-05] 2026-10-05：用戶表示 Spotpear AI Toy（即 toy-ai-core-c3-1.54，env 改名 spotpear-ai-toy）大概率就是量產板；已和用戶跑通 app 綁定和完整對話。電池檢測的改板要求另立任務。 [2026-10-07] 2026-10-07：用戶定案 Spotpear AI Toy（toy-ai-core-c3-1.54，env spotpear-ai-toy）為量產板，不再等另一塊板。驗收改為在 Spotpear 上測完評分表，確認沒有否決性問題；仍缺 ①②⑥⑦。
A34: R-02 | B34: R | C34: 1 止血定案 | D34: 內容 | E34: 角色收窄到 5–8 個粵語陪伴角色 | F34: 進行中 | G34: 通過 | I34: 現有 40 多個角色大多來自上游：有侵權風險（Batman、Iron Man、Gandalf、Elsa's Frozen Mystery）、涉及醫療（Blood test pal、Luna the Epilepsy Guardian、Vax Buddy）、語氣不適合兒童（Kai Indiebrew 等），而且多數不是粵語。 | J34: personalities 表（is_hidden） server/fastapi/character_prompt.py supabase/migrations/ | K34: 只保留 5–8 個自己設計的粵語陪伴角色，其餘設為 is_hidden；每個角色按 3–6 歲設計：句子短、用詞簡單、一次只問一個問題，不講恐怖、暴力或需要識字的內容。 | L34: ① 查 personalities 表，未隱藏的只剩選定角色 ② Web 端角色列表只顯示這些 ③ 每個角色用 10 句粵語對話抽查：每次回覆不超過 3 句，用詞 3–6 歲聽得懂，一次只問一個問題 | M34: Q5 | N34: 用戶已確認角色陣容。本地 DB：① 未隱藏內建角色只剩 hk_ 6 個 ② localhost:3100 Children 頁只見 6 個、Story 頁只見叮叮兔/咪咪貓 ③ 每角色 10 句粵語，prompt 用伺服器同一套組裝、開場白按 pipecat 以 user 角色送出：gemma-4-26b 65/66 合格（1 句 4 句/2 問）；DeepSeek v4 flash 預設 reasoning 61/66（超標都只多 1–2 句）；全部無簡體、恐怖、拼字 | O34: f72652b | P34: [2026-09-30] Q5：3–6 歲 [2026-10-07] 每個角色現可按語言設定 MiniMax 聲線（personalities.voices，admin 角色頁有廣東話/普通話欄；commit 9557ce5，per-language-voices branch，未 push、雲端 migration 未 apply）。選定角色時可給每個角色一把不同的 Cantonese_* 聲線；MiniMax 只有 6 把粵語聲（男聲僅 PlayfulMan、ProfessionalHost（M)）。本地 AI Hulk/Iron Man 已設粵語聲並實際合成成功。 [2026-10-07] 未完成：(1) 角色陣容待用戶確認 (2) 線上 LLM 若是 minimax-m2.7 則③不過，需確認雲端 app_settings 的 llm_model（本地是 google/gemma-4-26b-a4b-it）(3) migration 未套到雲端，要加入 release runbook 的 migration 清單 (4) 頭像為佔位扁平圖。另：測試帳號自建的 AI Hulk 是自訂角色（creator_id 非空），不受隱藏影響，但屬 Marvel IP [2026-10-07] 條件：線上 LLM 要用 gemma-4-26b，或 DeepSeek v4 flash 開 reasoning；DeepSeek 關 reasoning（effort=none）只有 49/66，多數 4 句。待辦：migration 20261007170000 未套到雲端，下次發布的 runbook 要列入（連同 140000、160000）。另發現：OpenRouter 上 DeepSeek v4 flash 部分供應商壞——DeepInfra 回傳字面 <｜end▁of▁sentence｜>、Venice/Parasail 回空內容，用 DeepSeek 時要在 app_settings 的 provider_order 固定好的供應商
A35: R-03 | B35: R | C35: 1 止血定案 | D35: 工程 | E35: 移除不用的 Deno／Cloudflare 後端與上游預設主機 | F35: 已完成 | G35: 通過 | H35: 2026-10-07 | I35: 網頁端只連 FastAPI；Deno、Cloudflare 只剩韌體的編譯選項和佔位符，另外還留著上游的 Railway 主機（elato-pyserver-production.up.railway.app）。留著會增加維護面，也可能被誤設成連到別人的伺服器。 | J35: server/deno/ server/cloudflare/ firmware-arduino/src/Config.cpp:48, :67, :93 README.md | K35: 刪除兩個後端目錄；韌體只保留 FastAPI 路線（移除 VOICE_SERVER_DENO／_CLOUDFLARE 分支與 Railway 主機）；README 只描述 FastAPI。 | L35: ① grep 全 repo 找不到 deno.dev、workers.dev、railway.app、VOICE_SERVER_DENO、VOICE_SERVER_CLOUDFLARE ② 各板的 pio run 編譯通過 ③ FastAPI 測試通過 | N35: ① grep deno.dev|workers.dev|railway.app|VOICE_SERVER_DENO|VOICE_SERVER_CLOUDFLARE 全 repo → 只剩 seed.json 的任務描述本身 ② pio run 18 個 env 全 SUCCESS（S3 devkit/Waveshare/xmini-c3/Spotpear 各變體）③ FastAPI pytest 182 passed；另 tsc --noEmit 通過 | O35: c3c5249 | P35: [2026-10-07] 同時移除 ELATO_MODE（Railway + www.elatoai.com 及其證書）；前端 auth callback 原本在 NEXT_PUBLIC_VERCEL_ENV=production 時導去 elatoai.com，改為讀 runtime 的 SITE_URL（預設 localhost:3000）——部署時要在 frontend .env.production 設 SITE_URL
A36: R-04 | B36: R | C36: 2 內測準備 | D36: 體驗 | E36: 粵語質量評測 | F36: 未開始 | G36: 未測試 | I36: 香港市場的核心體驗還沒驗證：LLM 可能輸出書面語而不是口語粵語；Azure 對兒童聲音的識別率未知；中英夾雜（「我今日去咗 playground」）未測。 | J36: server/fastapi/language_profiles.py server/fastapi/models/stt/azure.py OpenRouter 模型設定（admin 頁） | K36: 有一套粵語評測集（兒童錄音＋文字提示）；選定的 STT 與 LLM 達到門檻：兒童語音字錯率 ≤15%、口語粵語回覆 ≥90%、中英夾雜句能正確理解。 | L36: ① 30 段 3–6 歲兒童的粵語錄音（3 歲、4–5 歲、6 歲都要有，含中英夾雜）測 STT 字錯率 ② 50 條提示比較 2–3 個候選 LLM 的口語粵語比例 ③ 結果與腳本放在 server/fastapi/evals/ | P36: 門檻是建議值，可按首輪結果與你討論後調整。 [2026-09-30] Q5：3–6 歲；3 歲發音較不清，字錯率門檻可能要按首輪結果再討論
A37: R-05 | B37: R | C37: 2 內測準備 | D37: 硬件 | E37: 內測版外殼（3D 打印 20 台） | F37: 未開始 | G37: 未測試 | I37: 內測家庭需要能直接給小朋友用的外殼；GPIO0 是唯一能喚醒、也是按住說話的鍵，必須做成小朋友按得到的大按鍵。 | J37: 選定板子的尺寸圖與腳位 | K37: 20 台裝殼完成：大按鍵對應 GPIO0；喇叭與麥克風開孔不影響聲音；能充電、看得到燈號；沒有尖角和可吞食的小零件。 | L37: ① 裝殼前後各測一次喇叭響度與 1 米收音 ② 3 歲、4–5 歲、6 歲各至少一位小朋友試用：按得動大按鍵，並理解「按住說話、放開聽回覆」 ③ 1 米高跌落測試，沒有零件脫落 | M37: R-01 | P37: [2026-09-30] Q5：3–6 歲 [2026-10-12] 2026-10-12：外殼改為玩具廠做毛公仔＋內置機芯盒；內部測試用工廠第二版樣品（W4 約 20 隻）代替 3D 打印外殼。
A38: R-06 | B38: R | C38: 2 內測準備 | D38: 體驗 | E38: 家長自助上手流程 | F38: 未開始 | G38: 未測試 | I38: 內測家庭要自己安裝；配網、認領、選角色的流程從沒讓非開發者試過。 | J38: firmware-arduino/src/WifiManager.cpp（配網） frontend-nextjs 認領與設定頁 | K38: 家長只看盒內說明，10 分鐘內從開箱到第一次對話。 | L38: 找 3 位非團隊成員從零開始，記錄耗時與卡住的步驟；3 人都在 10 分鐘內完成。 | M38: P0-11 | P38: [2026-10-09] 2026-10-09 配網熱點由所有板同名的 ELATO-DEVICE 改為 AIBuddy-XXXX（STA MAC 尾 4 位，22ce0ae），App 的「找不到設備」提示同步改；雲端 1.0.1 已 OTA 推出。62:70 用手機連 AIBuddy-6270 配網成功。家長自助流程本身仍未找非團隊成員測試
A39: R-07 | B39: R | C39: 3 封閉內測 | D39: 內測 | E39: 20 個家庭封閉內測 | F39: 未開始 | G39: 未測試 | I39: 還不知道孩子會不會持續使用，也不知道真實使用量與每台成本。 | J39: turn_metrics admin 頁 | K39: 改為內部測試（2026-10-12 用戶決定，原為 20 個外部家庭）：團隊成員及家人用 20 台至少 4 週，三個品牌（馬會快活、政協青年聯會版、AI Buddy）的角色都要測；每週記錄：每次對話輪數、首字延遲 p95、每台每月成本、安全事件數、崩潰與斷線次數、測試者回饋。 | L39: 第 4 週結束時出一份內部測試報告，上面每個指標都有數據。 | M39: R-13 | P39: 依賴包含第 1、2 階段的全部安全項：P0 沒過不讓真實家庭使用。 [2026-09-30] 新的權限項也要在內測前完成 [2026-10-05] 改為以 CP1（R-13）把關：R-13 已涵蓋原有全部依賴。 [2026-10-12] 2026-10-12 用戶決定 11 月的 20 個家庭內測改為內部測試（標題保留原文）。不再需要外部家庭的內測同意書；代價是上市前沒有真實家庭的留存和兒童語音數據，R-04 用同事孩子的錄音補上，1/29 交付後兩週每天看數據。
A40: R-08 | B40: R | C40: 3 封閉內測 | D40: 決策 | E40: 第 8 週關卡決策 | F40: 未開始 | G40: 未測試 | I40: 批量數量、定價、是否延期都要用內測數據決定，不能事前拍板。 | J40: R-07 內測報告 P2-09 成本數據 | K40: CP2：11/27 前寫下決定及依據：① 品牌 C（AI Buddy 自有 IP）的首批數量，以及是否 1/15 出貨（品牌 A 馬會 2,500、品牌 B 政協青年聯會版 500 已定）② 品牌 C 的一次性售價及包含幾年服務（不收月費；A、B 按合約）③ 是否延期（任何 P0 沒過就不出貨）。同時硬件認證必須已送測（P1-08），量產外殼按決定的數量落單（R-09）。CP2 遲超過 2 週，就要評估新年前交付的風險。 | L40: 決策文件經你確認。 | M40: R-07, P2-09, P1-08 | P40: [2026-10-05] 2026-10-05：定為 CP2；收費方式已定為一次性付款、不收月費。 [2026-10-12] 2026-10-12 用戶確認三個品牌與數量：A 香港賽馬會（快活）2,500 隻、B 政協青年聯會版 500 隻、C 自家 AI Buddy（自有 IP）未定。量產板最遲 11/6 按 3,000 台加備品落單，早於 CP2。 [2026-10-12] 2026-10-12：品牌 B 政協青年聯會版的用戶是成人會員；品牌 C 即現有的 AI Buddy 兒童陪伴版（3–6 歲）。A、B 都是成人，兒童專屬項（P1-09 家長鎖、P1-04 的家長同意部分、R-12 每日上限）只在 C 出貨時才卡出貨。 [2026-10-13] 2026-10-13：1/15 只出快活和政協青年聯會兩個品牌（AI Buddy 延後），Tool call 只做調音量和結束對話，RAG v1 只放馬會第一批資料（答對率 80%，婉拒貼士 100%）。關卡決策按這個範圍做。
...

Sheet 待確認問題
A1: 編號 | B1: 問題 | C1: 為什麼重要 | D1: 影響的任務 | E1: 狀態 | F1: 回答 | G1: 回答日期
A2: Q1 | B2: 目標市場與孩子的年齡層是？ | C2: 決定要符合香港 PDPO、內地 PIPL、美國 COPPA 還是歐盟 GDPR-K，以及需要哪些硬件認證。 | D2: P1-04, P1-05, P1-08 | E2: 已回覆 | F2: 首發香港（粵語）；第一階段做陪伴型 AI，之後再加學習類角色。孩子年齡層未定。 | G2: 2026-09-30
A3: Q2 | B3: elatoai.hkqft.com 目前有沒有真實家庭在使用？ | C3: 有的話全部 P0 要立即處理，並要考慮是否需要通知用戶。 | D3: P0-01（全部 P0 的緊急程度） | E3: 已回覆 | F3: 目前沒有真實家庭使用（2026-09-30 確認）。 | G3: 2026-09-30
A4: Q3 | B4: 韌體打算閉源商業銷售嗎？ | C4: 決定 GPL／LGPL 依賴要開源還是替換。 | D4: P1-06, P1-07 | E4: 待回覆
A5: Q4 | B5: 第一年計劃多少台設備？ | C5: 決定擴展與成本相關工作的優先次序。 | D5: P2-08, P2-09（優先次序） | E5: 已回覆 | F5: 3 個月內（約 2026 年底）小批量 100–500 台，用現成板換殼；板子在 Waveshare S3 Audio 與一塊未到貨、類似 xmini-c3 的新板之間選。收費方式未定。 | G5: 2026-09-30
A6: Q5 | B6: 孩子的目標年齡層是幾歲？ | C6: 決定角色的說話方式與話題範圍、內容審核的尺度，以及粵語評測要錄哪個年齡的聲音。 | D6: R-02, R-04, P1-01 | E6: 已回覆 | F6: 3–6 歲。 | G6: 2026-09-30
A7: Q6 | B7: 家長可以自己建立角色嗎？ | C7: 決定角色表的權限與內容安全的把關方式。 | D7: P0-15, R-02 | E7: 已回覆 | F7: v1 關閉，只用內容管理員管理的精選角色。 | G7: 2026-09-30
A8: Q7 | B8: 管理員能不能看孩子的對話和記憶？ | C8: 兒童資料的最小權限原則；決定管理端、資料庫權限和審核事件要記什麼。 | D8: P0-12, P1-01, P1-11 | E8: 已回覆 | F8: 完全不能：網頁管理端和資料庫權限都不給；審核事件只記類別，不記原文。 | G8: 2026-09-30
A9: Q8 | B9: 一個家庭帳號的結構？ | C9: 決定資料表和家長端的權限範圍。 | D9: P0-12 | E9: 已回覆 | F9: v1 維持 1 個家長帳號、1 個孩子、1 台設備。 | G9: 2026-09-30
A10: Q9 | B10: 管理員分幾種角色？ | C10: 最小權限：誰能改角色、誰能改系統設定、誰能動設備。 | D10: P0-12, R-11 | E10: 已回覆 | F10: v1 兩種：超級管理員、內容管理員。客服工具照做，暫由超級管理員使用；客服角色之後有需要再加。 | G10: 2026-09-30
A11: Q10 | B11: 燒錄和出廠自檢在哪裡做：板子供應商出貨前預燒、玩具廠設工位，還是我們自己做？ | C11: 決定出廠腳本、自檢工位和作業指導書按哪種場地準備（W8 要交工廠），以及設備密鑰會不會經過供應商。建議：Spotpear 燒共用、不含密鑰的韌體；玩具廠裝機芯盒工位用我方電腦寫密鑰、選品牌款式、開加密、自檢、登記。最遲 11/6 定。 | D11: R-10 | E11: 已回覆 | F11: 2026-10-12 用戶決定：燒共用韌體。Spotpear 出貨前代燒所有品牌共用、不含密鑰的出廠韌體，附每片 MAC 清單；每台的設備密鑰、品牌和款式、自檢、登記在玩具廠裝機芯盒工位，用我方電腦和腳本經序列埠完成。 | G11: 2026-10-12
A12: Q11 | B12: 馬會快活的賽馬日版和新春版各多少隻（共 2,500）？ | C12: 兩款的服裝和配件要分開訂料；11/20 前不知道，PP 樣和大貨單（11/27）會被拖慢。由馬會決定。 | D12: R-09, R-15 | E12: 待回覆
A13: Q12 | B13: 快活 App 的「會員綁定」是指甚麼：用我們自己的帳號（email 驗證碼），還是接馬會的會員帳號登入（SSO）？ | C13: 接馬會 SSO 的話，登入、帳號刪除和資料歸屬都要按馬會的介面重做，工作量和排期要另估，而且 W5（11/9–11/13）就要做快活 App 的綁定；用我們的帳號則和其他品牌共用同一套流程。由馬會決定，要盡早問。 | D13: P0-11, 快活 App（未入追蹤表） | E13: 待回覆
A14: Q13 | B14: 政協青年聯會版的角色、語言和內容由誰提供？什麼時候交？ | C14: 品牌 B 的用戶是成人會員，但角色、說話語言、內容規則都還沒有。最遲 11/13 要拿到，才趕得及內部測試和 App 頁面（W6）。 | D14: 品牌 B 的 App 頁面 | E14: 待回覆

Sheet 更新記錄
A1: 時間 | B1: 編號 | C1: 任務 / 問題 | D1: 舊狀態 | E1: 新狀態 | F1: 測試結果 | G1: 測試證據 | H1: Commit | I1: 備註
A2: 2026-09-30 09:17 | B2: — | C2: 建立追蹤表 | I2: 依據 2026-09-30 的生產就緒評估建立：31 項任務、4 個待確認問題
A3: 2026-09-30 11:35 | B3: Q1 | C3: 目標市場與孩子的年齡層是？ | D3: 待回覆 | E3: 已回覆 | I3: 首發香港（粵語）；第一階段做陪伴型 AI，之後再加學習類角色。孩子年齡層未定。
A4: 2026-09-30 11:35 | B4: Q2 | C4: elatoai.hkqft.com 目前有沒有真實家庭在使用？ | D4: 待回覆 | E4: 已回覆 | I4: 目前沒有真實家庭使用（2026-09-30 確認）。
A5: 2026-09-30 11:35 | B5: Q4 | C5: 第一年計劃多少台設備？ | D5: 待回覆 | E5: 已回覆 | I5: 3 個月內（約 2026 年底）小批量 100–500 台，用現成板換殼；板子在 Waveshare S3 Audio 與一塊未到貨、類似 xmini-c3 的新板之間選。收費方式未定。
A6: 2026-09-30 11:43 | B6: R-01 | C6: 選定量產板子 | E6: 未開始 | I6: 新增任務（從 seed.json 同步）
A7: 2026-09-30 11:43 | B7: R-02 | C7: 角色收窄到 5–8 個粵語陪伴角色 | E7: 未開始 | I7: 新增任務（從 seed.json 同步）
A8: 2026-09-30 11:43 | B8: R-03 | C8: 移除不用的 Deno／Cloudflare 後端與上游預設主機 | E8: 未開始 | I8: 新增任務（從 seed.json 同步）
A9: 2026-09-30 11:43 | B9: R-04 | C9: 粵語質量評測 | E9: 未開始 | I9: 新增任務（從 seed.json 同步）
A10: 2026-09-30 11:43 | B10: R-05 | C10: 內測版外殼（3D 打印 20 台） | E10: 未開始 | I10: 新增任務（從 seed.json 同步）
A11: 2026-09-30 11:43 | B11: R-06 | C11: 家長自助上手流程 | E11: 未開始 | I11: 新增任務（從 seed.json 同步）
A12: 2026-09-30 11:43 | B12: R-07 | C12: 20 個家庭封閉內測 | E12: 未開始 | I12: 新增任務（從 seed.json 同步）
A13: 2026-09-30 11:43 | B13: R-08 | C13: 第 8 週關卡決策 | E13: 未開始 | I13: 新增任務（從 seed.json 同步）
A14: 2026-09-30 11:43 | B14: R-09 | C14: 量產外殼（真空複模） | E14: 未開始 | I14: 新增任務（從 seed.json 同步）
A15: 2026-09-30 11:43 | B15: R-10 | C15: 出廠流程 | E15: 未開始 | I15: 新增任務（從 seed.json 同步）
A16: 2026-09-30 11:43 | B16: R-11 | C16: 售後：客服、保修與換機 | E16: 未開始 | I16: 新增任務（從 seed.json 同步）
A17: 2026-09-30 11:43 | B17: Q5 | C17: 孩子的目標年齡層是幾歲？ | E17: 待回覆 | I17: 新增待確認問題（從 seed.json 同步）
A18: 2026-09-30 11:43 | B18: — | C18: 同步表格 | I18: 版面更新到最新版；新增 11 項任務、1 個問題；為 31 項任務填入階段
A19: 2026-09-30 11:43 | B19: P0-01 | C19: 確認線上環境的暴露面 | D19: 未開始 | E19: 不適用 | I19: Q2：目前沒有真實家庭使用，緊急度已確定；線上驗證改為每項修復部署後各自做。
A20: 2026-09-30 11:43 | B20: P1-08 | C20: 硬件認證 | D20: 未開始 | E20: 未開始 | I20: 送測需要定案的板子和外殼樣品；修改了依賴→Q1, R-01, R-05
A21: 2026-09-30 11:43 | B21: P0-14 | C21: 韌體簽章、Secure Boot 與 Flash 加密 | D21: 未開始 | E21: 未開始 | I21: Secure Boot 要在定案的板子上驗證；修改了依賴→P0-13, R-01
A22: 2026-09-30 11:46 | B22: Q5 | C22: 孩子的目標年齡層是幾歲？ | D22: 待回覆 | E22: 已回覆 | I22: 3–6 歲。
A23: 2026-09-30 11:46 | B23: R-02 | C23: 角色收窄到 5–8 個粵語陪伴角色 | D23: 未開始 | E23: 未開始 | I23: Q5：3–6 歲；修改了驗收標準、測試方法
A24: 2026-09-30 11:46 | B24: R-04 | C24: 粵語質量評測 | D24: 未開始 | E24: 未開始 | I24: Q5：3–6 歲；3 歲發音較不清，字錯率門檻可能要按首輪結果再討論；修改了測試方法
A25: 2026-09-30 11:46 | B25: R-05 | C25: 內測版外殼（3D 打印 20 台） | D25: 未開始 | E25: 未開始 | I25: Q5：3–6 歲；修改了測試方法
A26: 2026-09-30 11:50 | B26: R-12 | C26: 家長控制：每日使用上限和休息時段 | E26: 未開始 | I26: 新增任務
A27: 2026-09-30 15:01 | B27: P0-15 | C27: 角色表權限：只有內容管理員能發佈，關閉家長自建角色 | E27: 未開始 | I27: 新增任務
A28: 2026-09-30 15:01 | B28: P0-16 | C28: 移除「醫生」身份與寫死的通關碼 | E28: 未開始 | I28: 新增任務
A29: 2026-09-30 15:01 | B29: P1-09 | C29: 家長鎖：孩子模式進設定要輸入 PIN | E29: 未開始 | I29: 新增任務
A30: 2026-09-30 15:01 | B30: P1-10 | C30: 管理操作審計記錄 | E30: 未開始 | I30: 新增任務
A31: 2026-09-30 15:01 | B31: P1-11 | C31: 伺服器與資料庫直接存取的管控 | E31: 未開始 | I31: 新增任務
A32: 2026-09-30 15:01 | B32: P0-12 | C32: 收緊 Admin 權限與路由保護 | D32: 未開始 | E32: 未開始 | I32: 權限設計討論後擴大範圍：見 Q7、Q9；修改了驗收標準、測試方法
A33: 2026-09-30 15:01 | B33: P1-01 | C33: 加入內容審核層（輸入與輸出） | D33: 未開始 | E33: 未開始 | I33: Q5：3–6 歲；Q7：事件不記原文；修改了驗收標準、測試方法
A34: 2026-09-30 15:01 | B34: R-07 | C34: 20 個家庭封閉內測 | D34: 未開始 | E34: 未開始 | I34: 新的權限項也要在內測前完成；修改了依賴→P0-02, P0-03, P0-04, P0-05, P0-06, P0-07, P0-08, P0-09, P0-10, P0-11, P0-12, P0-13, P1-01, P1-02, P2-09, R-01, R-02, R-04, R-05, R-06, P0-15, P0-16, P1-09, P1-11
A35: 2026-09-30 15:01 | B35: R-11 | C35: 售後：客服、保修與換機 | D35: 未開始 | E35: 未開始 | I35: v1 沒有客服角色，售後工具由超級管理員使用（Q9）
A36: 2026-09-30 15:01 | B36: Q6 | C36: 家長可以自己建立角色嗎？ | E36: 待回覆 | I36: 新增待確認問題
A37: 2026-09-30 15:01 | B37: Q6 | C37: 家長可以自己建立角色嗎？ | D37: 待回覆 | E37: 已回覆 | I37: v1 關閉，只用內容管理員管理的精選角色。
A38: 2026-09-30 15:01 | B38: Q7 | C38: 管理員能不能看孩子的對話和記憶？ | E38: 待回覆 | I38: 新增待確認問題
A39: 2026-09-30 15:01 | B39: Q7 | C39: 管理員能不能看孩子的對話和記憶？ | D39: 待回覆 | E39: 已回覆 | I39: 完全不能：網頁管理端和資料庫權限都不給；審核事件只記類別，不記原文。
A40: 2026-09-30 15:01 | B40: Q8 | C40: 一個家庭帳號的結構？ | E40: 待回覆 | I40: 新增待確認問題
...
